<?xml version="1.0" ?>
<sdf version="1.7">
  <world name='world_demo'>
    <physics name="1ms" type="ode">
      <max_step_size>0.004</max_step_size> 
      <real_time_factor>1.0</real_time_factor>
    </physics>
    <plugin
      filename="gz-sim-physics-system"
      name="gz::sim::systems::Physics">
    </plugin>
    <plugin
      filename="gz-sim-user-commands-system"
      name="gz::sim::systems::UserCommands">
    </plugin>
    <plugin
      filename="gz-sim-scene-broadcaster-system"
      name="gz::sim::systems::SceneBroadcaster">
    </plugin>

    <gui fullscreen="0">

      <!-- 3D scene -->
      <plugin filename="MinimalScene" name="3D View">
        <gz-gui>
          <title>3D View</title>
          <property type="bool" key="showTitleBar">false</property>
          <property type="string" key="state">docked</property>
        </gz-gui>

        <engine>ogre2</engine>
        <scene>scene</scene>
        <ambient_light>0.4 0.4 0.4</ambient_light>
        <background_color>0.8 0.8 0.8</background_color>
        <camera_pose>-0.5 0 0.5 0 0.5 0</camera_pose>
        <camera_clip>
          <near>0.01</near>
          <far>1000</far>
        </camera_clip>
      </plugin>
      <plugin filename="GzSceneManager" name="Scene Manager">
        <gz-gui>
          <property key="resizable" type="bool">false</property>
          <property key="width" type="double">5</property>
          <property key="height" type="double">5</property>
          <property key="state" type="string">floating</property>
          <property key="showTitleBar" type="bool">false</property>
        </gz-gui>
      </plugin>

      <!-- World control -->
      <plugin filename="WorldControl" name="World control">
        <gz-gui>
          <title>World control</title>
          <property type="bool" key="showTitleBar">false</property>
          <property type="bool" key="resizable">false</property>
          <property type="double" key="height">72</property>
          <property type="double" key="width">121</property>
          <property type="double" key="z">1</property>

          <property type="string" key="state">floating</property>
          <anchors target="3D View">
          <line own="left" target="left"/>
          <line own="bottom" target="bottom"/>
          </anchors>
        </gz-gui>

        <play_pause>true</play_pause>
        <step>true</step>
        <start_paused>false</start_paused>
        <service>/world/world_demo/control</service>
        <stats_topic>/world/world_demo/stats</stats_topic>
      </plugin>
      
      <!-- World statistics -->
      <plugin filename="WorldStats" name="World stats">
        <gz-gui>
          <title>World stats</title>
          <property type="bool" key="showTitleBar">false</property>
          <property type="bool" key="resizable">false</property>
          <property type="double" key="height">110</property>
          <property type="double" key="width">290</property>
          <property type="double" key="z">1</property>

          <property type="string" key="state">floating</property>
          <anchors target="3D View">
          <line own="right" target="right"/>
          <line own="bottom" target="bottom"/>
          </anchors>
        </gz-gui>
        <sim_time>true</sim_time>
        <real_time>true</real_time>
        <real_time_factor>true</real_time_factor>
        <iterations>true</iterations>
        <topic>/world/world_demo/stats</topic>

      </plugin>
      
      <!-- Toolbar (required for camera controls) -->
      <plugin filename="InteractiveViewControl" name="View Angle">
        <gz-gui>
          <title>View Angle</title>
          <property type="bool" key="showTitleBar">false</property>
          <property type="string" key="state">docked</property>
        </gz-gui>
      </plugin>

      <!-- Display Transform Control Toolbar -->
      <plugin filename="TransformControl" name="Transform Control">
        <gz-gui>
          <property type="bool" key="showTitleBar">false</property>
         <property type="string" key="state">docked</property>
        </gz-gui>
      </plugin>
        
      <!-- Entity tree -->
      <plugin filename="EntityTree" name="Entity tree">
      </plugin>

      <!--using keyboard to control arm-->
      <plugin filename="KeyPublisher" name="Key Publisher"/>
    </gui>

    <!--Light-->
    <light type="directional" name="sun">
      <cast_shadows>true</cast_shadows>
      <pose>0 0 10 0 0 0</pose>
      <diffuse>0.8 0.8 0.8 1</diffuse>
      <specular>0.2 0.2 0.2 1</specular>
      <attenuation>
        <range>1000</range>
        <constant>0.9</constant>
        <linear>0.01</linear>
        <quadratic>0.001</quadratic>
      </attenuation>
      <direction>-0.5 0.1 -0.9</direction>
    </light>  

    <!--Build a ground plane-->
    <model name="ground_plane">
      <static>true</static>
      <link name="link">
        <collision name="collision">
        <geometry>
          <plane>
          <normal>0 0 1</normal>
          </plane>
        </geometry>
        </collision>
        <visual name="visual">
        <geometry>
          <plane>
          <normal>0 0 1</normal>
          <size>100 100</size>
          </plane>
        </geometry>
        <material>
          <ambient>0.8 0.8 0.8 1</ambient>
          <diffuse>0.8 0.8 0.8 1</diffuse>
          <specular>0.8 0.8 0.8 1</specular>
        </material>
        </visual>
      </link>
    </model>  

    <!--Robot itself-->
    <model name='Robot_arm'>
    
      <joint name='fixed_base_joint' type='fixed'>
        <pose relative_to='__model__'>0 0 0.05 0 0 0</pose>
        <parent>world</parent>
        <child>base_link</child>
      </joint>
      
      <link name='base_link'>
        <pose relative_to='fixed_base_joint'>0 0 0 0 0 0</pose>
        <inertial>
          <pose>-0.0032047 0.024483999999999999 4.2786999999999999e-10 0 0 0</pose>
          <mass>0.10228</mass> <!--kgs-->
          <inertia>
            <ixx>4.5355000000000002e-05</ixx>
            <ixy>-2.7911999999999997e-07</ixy>
            <ixz>1.5618e-13</ixz>
            <iyy>8.4568999999999996e-05</iyy>
            <iyz>-6.4687999999999997e-13</iyz>
            <izz>4.8900999999999998e-05</izz>
          </inertia>
        </inertial>
        <collision name='base_link_collision'>
          <pose>0 0 0 0 0 0</pose>
          <geometry>
            <mesh>
              <scale>1 1 1</scale>
              <uri>package:///home/user/robot_arm_ws/src/robot_arm/meshes/base_link.stl</uri>
            </mesh>
          </geometry>
        </collision>
        <visual name='base_link_visual'>
          <pose>0 0 0 -1.5708 0 0</pose>
          <geometry>
            <mesh>
              <scale>1 1 1</scale>
              <uri>package:///home/user/robot_arm_ws/src/robot_arm/meshes/base_link.stl</uri>
            </mesh>
          </geometry>
          <material>
            <diffuse>0.990199983 1 1 1</diffuse>
            <ambient>0.990199983 1 1 1</ambient>
          </material>
        </visual>
      </link>
      <joint name='joint_0' type='revolute'>
        <pose relative_to='base_link'>0 0 0 0 0 0</pose>
        <parent>base_link</parent>
        <child>base_2</child>
        <axis>
          <xyz>0 0 1</xyz>
          <limit>
            <lower>0</lower>
            <upper>3.14</upper>
            <effort>1.372931</effort>
            <velocity>1</velocity>
          </limit>
          <dynamics>
            <spring_reference>0</spring_reference>
            <spring_stiffness>0</spring_stiffness>
          </dynamics>
        </axis>
      </joint>
      <plugin
  name="gz::sim::systems::JointPositionController"
  filename="gz-sim-joint-position-controller-system">
        <joint_name>joint_0</joint_name>
        <topic>joint_0/position_cmd</topic>
      </plugin>
      <link name='base_2'>
        <pose relative_to='joint_0'>0 0 0 0 0 0</pose>
        <inertial>
          <pose>0.0053512000000000004 0.0066633999999999999 0.016105999999999999 0 0 0</pose>
          <mass>0.11218</mass>
          <inertia>
            <ixx>3.2270000000000001e-05</ixx>
            <ixy>4.2049000000000002e-06</ixy>
            <ixz>3.5683999999999998e-10</ixz>
            <iyy>3.3584000000000002e-05</iyy>
            <iyz>-2.6844999999999999e-10</iyz>
            <izz>5.6759000000000003e-05</izz>
          </inertia>
        </inertial>
        <collision name='base_2_collision'>
          <pose>0 0 0 0 0 0</pose>
          <geometry>
            <mesh>
              <scale>1 1 1</scale>
              <uri>package:///home/user/robot_arm_ws/src/robot_arm/meshes/base_2.stl</uri>
            </mesh>
          </geometry>
        </collision>
        <visual name='base_2_visual'>
          <pose>0 0 0 0 0 0</pose>
          <geometry>
            <mesh>
              <scale>1 1 1</scale>
              <uri>package:///home/user/robot_arm_ws/src/robot_arm/meshes/base_2.stl</uri>
            </mesh>
          </geometry>
          <material>
            <diffuse>0.990199983 1 1 1</diffuse>
            <ambient>0.990199983 1 1 1</ambient>
          </material>
        </visual>
      </link>
      <joint name='joint_1' type='revolute'>
        <pose relative_to='base_2'>0.015952999999999998 0.0050523 0.021250000000000002 1.5708 -1.1102230246251565e-16 -0.64209999999999989</pose>
        <parent>base_2</parent>
        <child>link_1</child>
        <axis>
          <xyz>0 0 1</xyz>
          <limit>
            <lower>0</lower>
            <upper>3.14</upper>
            <effort>2.2555295</effort>
            <velocity>1</velocity>
          </limit>
          <dynamics>
            <spring_reference>0</spring_reference>
            <spring_stiffness>0</spring_stiffness>
          </dynamics>
        </axis>
      </joint>
      <plugin
  name="gz::sim::systems::JointPositionController"
  filename="gz-sim-joint-position-controller-system">
        <joint_name>joint_1</joint_name>
        <topic>/joint_1/position_cmd</topic>
      </plugin>
      <link name='link_1'>
        <pose relative_to='joint_1'>0 0 0 0 0 0</pose>
        <inertial>
          <pose>0.055479146169598398 0.00176442609004313 0.0290000000014588 0 0 0</pose>
          <mass>0.030979313863850701</mass>
          <inertia>
            <ixx>1.6983690284737e-06</ixx>
            <ixy>-1.1158363147447101e-06</ixy>
            <ixz>-1.1057093448679199e-15</ixz>
            <iyy>4.2176528052676398e-05</iyy>
            <iyz>-2.9342353482221499e-17</iyz>
            <izz>4.3745816606717402e-05</izz>
          </inertia>
        </inertial>
        <collision name='link_1_collision'>
          <pose>0 0 0 0 0 0</pose>
          <geometry>
            <mesh>
              <scale>1 1 1</scale>
              <uri>package:///home/user/robot_arm_ws/src/robot_arm/meshes/link_1.stl</uri>
            </mesh>
          </geometry>
        </collision>
        <visual name='link_1_visual'>
          <pose>0 0 0 0 0 0</pose>
          <geometry>
            <mesh>
              <scale>1 1 1</scale>
              <uri>package:///home/user/robot_arm_ws/src/robot_arm/meshes/link_1.stl</uri>
            </mesh>
          </geometry>
          <material>
            <diffuse>0.990196109 1 1 1</diffuse>
            <ambient>0.990196109 1 1 1</ambient>
          </material>
        </visual>
      </link>
      <joint name='joint_2' type='revolute'>
        <pose relative_to='link_1'>0.10996 0.0030289000000000002 0.0050000000000000001 0 0 -1.57</pose>
        <parent>link_1</parent>
        <child>link_2</child>
        <axis>
          <xyz>0 0 1</xyz>
          <limit>
            <lower>0</lower>
            <upper>3.14</upper>
            <effort>1.372931</effort>
            <velocity>1</velocity>
          </limit>
          <dynamics>
            <spring_reference>0</spring_reference>
            <spring_stiffness>0</spring_stiffness>
          </dynamics>
        </axis>
      </joint>
      <plugin
  name="gz::sim::systems::JointPositionController"
  filename="gz-sim-joint-position-controller-system">
        <joint_name>joint_2</joint_name>
        <topic>/joint_2/position_cmd</topic>
      </plugin>
      <link name='link_2'>
        <pose relative_to='joint_2'>0 0 0 0 0 0</pose>
        <inertial>
          <pose>0.084735000000000005 0.0016229 0.027324999999999999 0 0 0</pose>
          <mass>0.10106</mass>
          <inertia>
            <ixx>1.4167e-05</ixx>
            <ixy>-1.7618e-06</ixy>
            <ixz>7.8929000000000001e-14</ixz>
            <iyy>0.00011671999999999999</iyy>
            <iyz>-6.2134999999999997e-15</iyz>
            <izz>0.00011195</izz>
          </inertia>
        </inertial>
        <collision name='link_2_collision'>
          <pose>0 0 0 0 0 0</pose>
          <geometry>
            <mesh>
              <scale>1 1 1</scale>
              <uri>package:///home/user/robot_arm_ws/src/robot_arm/meshes/link_2.stl</uri>
            </mesh>
          </geometry>
        </collision>
        <visual name='link_2_visual'>
          <pose>0 0 0 0 0 0</pose>
          <geometry>
            <mesh>
              <scale>1 1 1</scale>
              <uri>package:///home/user/robot_arm_ws/src/robot_arm/meshes/link_2.stl</uri>
            </mesh>
          </geometry>
          <material>
            <diffuse>0.313724995 0.313724995 0.313724995 1</diffuse>
            <ambient>0.313724995 0.313724995 0.313724995 1</ambient>
          </material>
        </visual>
      </link>
      <joint name='joint_3' type='revolute'>
        <pose relative_to='link_2'>0.16947000000000001 0.0034106000000000002 0 0 0 1.57</pose>
        <parent>link_2</parent>
        <child>Link_3</child>
        <axis>
          <xyz>0 0 -1</xyz>
          <limit>
            <lower>0</lower>
            <upper>3.14</upper>
            <effort>1.372931</effort>
            <velocity>1</velocity>
          </limit>
          <dynamics>
            <spring_reference>0</spring_reference>
            <spring_stiffness>0</spring_stiffness>
          </dynamics>
        </axis>
      </joint>
      <plugin
  name="gz::sim::systems::JointPositionController"
  filename="gz-sim-joint-position-controller-system">
        <joint_name>joint_3</joint_name>
        <topic>/joint_3/position_cmd</topic>
      </plugin>
      <link name='Link_3'>
        <pose relative_to='joint_3'>0 0 0 0 0 0</pose>
        <inertial>
          <pose>0.030036 0.0038519000000000001 0.018824 0 0 0</pose>
          <mass>0.029773999999999998</mass>
          <inertia>
            <ixx>2.6711000000000001e-06</ixx>
            <ixy>1.8741999999999999e-07</ixy>
            <ixz>-3.5401e-08</ixz>
            <iyy>5.8292e-06</iyy>
            <iyz>3.0644999999999999e-09</iyz>
            <izz>4.0041000000000003e-06</izz>
          </inertia>
        </inertial>
        <collision name='Link_3_collision'>
          <pose>0 0 0 0 0 0</pose>
          <geometry>
            <mesh>
              <scale>1 1 1</scale>
              <uri>package:///home/user/robot_arm_ws/src/robot_arm/meshes/Link_3.stl</uri>
            </mesh>
          </geometry>
        </collision>
        <visual name='Link_3_visual'>
          <pose>0 0 0 0 0 0</pose>
          <geometry>
            <mesh>
              <scale>1 1 1</scale>
              <uri>package:///home/user/robot_arm_ws/src/robot_arm/meshes/Link_3.stl</uri>
            </mesh>
          </geometry>
          <material>
            <diffuse>1 1 1 1</diffuse>
            <ambient>1 1 1 1</ambient>
          </material>
        </visual>
      </link>
      <joint name='joint_4' type='revolute'>
        <pose relative_to='Link_3'>0.060671000000000003 0.0093380000000000008 0.024594000000000001 1.5708 -4.2351647362715017e-22 -3.1415853071795872</pose>
        <parent>Link_3</parent>
        <child>link_4</child>
        <axis>
          <xyz>0.99982000000000004 0 -0.01873</xyz>
          <limit>
            <lower>0</lower>
            <upper>3.14</upper>
            <effort>1.372931</effort>
            <velocity>1</velocity>
          </limit>
          <dynamics>
            <spring_reference>0</spring_reference>
            <spring_stiffness>0</spring_stiffness>
          </dynamics>
        </axis>
      </joint>
      <plugin
  name="gz::sim::systems::JointPositionController"
  filename="gz-sim-joint-position-controller-system">
        <joint_name>joint_4</joint_name>
        <topic>/joint_4/position_cmd</topic>
      </plugin>
      <link name='link_4'>
        <pose relative_to='joint_4'>0 0 0 0 0 0</pose>
        <inertial>
          <pose>-0.031146 0.0017852 0.0028138 0 0 0</pose>
          <mass>0.032454999999999998</mass>
          <inertia>
            <ixx>2.8976999999999998e-06</ixx>
            <ixy>-4.2615000000000001e-08</ixy>
            <ixz>3.4246000000000001e-08</ixz>
            <iyy>3.5978000000000001e-06</iyy>
            <iyz>-4.9594000000000003e-07</iyz>
            <izz>5.1953e-06</izz>
          </inertia>
        </inertial>
        <collision name='link_4_collision'>
          <pose>0 0 0 0 0 0</pose>
          <geometry>
            <mesh>
              <scale>1 1 1</scale>
              <uri>package:///home/user/robot_arm_ws/src/robot_arm/meshes/link_4.stl</uri>
            </mesh>
          </geometry>
        </collision>
        <visual name='link_4_visual'>
          <pose>0 0 0 0 0 0</pose>
          <geometry>
            <mesh>
              <scale>1 1 1</scale>
              <uri>package:///home/user/robot_arm_ws/src/robot_arm/meshes/link_4.stl</uri>
            </mesh>
          </geometry>
          <material>
            <diffuse>0.990199983 1 1 1</diffuse>
            <ambient>0.990199983 1 1 1</ambient>
          </material>
        </visual>
      </link>
      <plugin 
      filename="gz-sim-joint-state-publisher-system"
      name="gz::sim::systems::JointStatePublisher">
        <joint_name>joint_0</joint_name>
        <joint_name>joint_1</joint_name>
        <joint_name>joint_2</joint_name>
        <joint_name>joint_3</joint_name>
        <joint_name>joint_4</joint_name>
        <update_rate>100</update_rate>
        <topic>/world/world_demo/joint_state</topic>
      </plugin>
    </model>
    


  </world>
</sdf>