<?xml version="1.0" encoding="utf-8"?>
<!-- This URDF was automatically created by SolidWorks to URDF Exporter! Originally created by Stephen Brawner (brawner@gmail.com) 
     Commit Version: 1.6.0-4-g7f85cfe  Build Version: 1.6.7995.38578
     For more information, please see http://wiki.ros.org/sw_urdf_exporter -->
<robot
  name="Robot_arm">
  <link name="world"/>
  <joint name="fixed_base_joint" type="fixed">
    <parent link="world"/>
    <child link="base_link"/>
    <origin xyz="0 0 0" rpy="0 0 0"/>
  </joint>
  <link
    name="base_link">
    <inertial>
      <origin
        xyz="-0.0032047 0.024484 4.2787E-10"
        rpy="0 0 0" />
      <mass
        value="0.10228" />
      <inertia
        ixx="4.5355E-05"
        ixy="-2.7912E-07"
        ixz="1.5618E-13"
        iyy="8.4569E-05"
        iyz="-6.4688E-13"
        izz="4.8901E-05" />
    </inertial>
    <visual>
      <origin
        xyz="0 0 0"
        rpy="-1.5708 0 0" />
      <geometry>
        <mesh
          filename="package://robot_arm/meshes/base_link.stl" />
      </geometry>
      <material
        name="">
        <color
          rgba="0.79216 0.81961 0.93333 1" />
      </material>
    </visual>
    <collision>
      <origin
        xyz="0 0 0"
        rpy="-1.5708 0 0" />
      <geometry>
        <mesh
          filename="package://robot_arm/meshes/base_link.stl" />
      </geometry>
    </collision>
  </link>
  <link
    name="base_2">
    <inertial>
      <origin
        xyz="0.0053512 0.0066634 0.016106"
        rpy="0 0 0" />
      <mass
        value="0.11218" />
      <inertia
        ixx="3.227E-05"
        ixy="4.2049E-06"
        ixz="3.5684E-10"
        iyy="3.3584E-05"
        iyz="-2.6845E-10"
        izz="5.6759E-05" />
    </inertial>
    <visual>
      <origin
        xyz="0 0 0"
        rpy="0 0 0" />
      <geometry>
        <mesh
          filename="package://robot_arm/meshes/base_2.stl" />
      </geometry>
      <material
        name="">
        <color
          rgba="0.79216 0.81961 0.93333 1" />
      </material>
    </visual>
    <collision>
      <origin
        xyz="0 0 0"
        rpy="0 0 0" />
      <geometry>
        <mesh
          filename="package://robot_arm/meshes/base_2.stl" />
      </geometry>
    </collision>
  </link>
  <joint
    name="joint_0"
    type="revolute">
    <origin
      xyz="0 0 0"
      rpy="0 0 0" />
    <parent
      link="base_link" />
    <child
      link="base_2" />
    <axis
      xyz="0 0 1" />
    <limit
      lower="0"
      upper="3.14"
      effort="1.176798"
      velocity="1" />
  </joint>
  <link
    name="link_1">
    <inertial>
      <origin
        xyz="0.0554791461695984 0.00176442609004313 0.0290000000014588"
        rpy="0 0 0" />
      <mass
        value="0.0309793138638507" />
      <inertia
        ixx="1.6983690284737E-06"
        ixy="-1.11583631474471E-06"
        ixz="-1.10570934486792E-15"
        iyy="4.21765280526764E-05"
        iyz="-2.93423534822215E-17"
        izz="4.37458166067174E-05" />
    </inertial>
    <visual>
      <origin
        xyz="0 0 0"
        rpy="0 0 0" />
      <geometry>
        <mesh
          filename="package://robot_arm/meshes/link_1.stl" />
      </geometry>
      <material
        name="">
        <color
          rgba="0.792156862745098 0.819607843137255 0.933333333333333 1" />
      </material>
    </visual>
    <collision>
      <origin
        xyz="0 0 0"
        rpy="0 0 0" />
      <geometry>
        <mesh
          filename="package://robot_arm/meshes/link_1.stl" />
      </geometry>
    </collision>
  </link>
  <joint
    name="joint_1"
    type="revolute">
    <origin
      xyz="0.015953 0.0050523 0.02125"
      rpy="1.5708 0 -0.6421" />
    <parent
      link="base_2" />
    <child
      link="link_1" />
    <axis
      xyz="0 0 1" />
    <limit
      lower="0"
      upper="3.14"
      effort="1.176798"
      velocity="1" />
  </joint>
  <link
    name="link_2">
    <inertial>
      <origin
        xyz="0.084735 0.0016229 0.027325"
        rpy="0 0 0" />
      <mass
        value="0.10106" />
      <inertia
        ixx="1.4167E-05"
        ixy="-1.7618E-06"
        ixz="7.8929E-14"
        iyy="0.00011672"
        iyz="-6.2135E-15"
        izz="0.00011195" />
    </inertial>
    <visual>
      <origin
        xyz="0 0 0"
        rpy="0 0 0" />
      <geometry>
        <mesh
          filename="package://robot_arm/meshes/link_2.stl" />
      </geometry>
      <material
        name="">
        <color
          rgba="0.25098 0.25098 0.25098 1" />
      </material>
    </visual>
    <collision>
      <origin
        xyz="0 0 0"
        rpy="0 0 0" />
      <geometry>
        <mesh
          filename="package://robot_arm/meshes/link_2.stl" />
      </geometry>
    </collision>
  </link>
  <joint
    name="joint_2"
    type="revolute">
    <origin
      xyz="0.10996 0.0030289 0.005"
      rpy="0 0 -1.57" />
    <parent
      link="link_1" />
    <child
      link="link_2" />
    <axis
      xyz="0 0 1" />
    <limit
      lower="0"
      upper="3.14"
      effort="1.176798"
      velocity="1" />
  </joint>
  <link
    name="Link_3">
    <inertial>
      <origin
        xyz="0.030036 0.0038519 0.018824"
        rpy="0 0 0" />
      <mass
        value="0.029774" />
      <inertia
        ixx="2.6711E-06"
        ixy="1.8742E-07"
        ixz="-3.5401E-08"
        iyy="5.8292E-06"
        iyz="3.0645E-09"
        izz="4.0041E-06" />
    </inertial>
    <visual>
      <origin
        xyz="0 0 0"
        rpy="0 0 0" />
      <geometry>
        <mesh
          filename="package://robot_arm/meshes/Link_3.stl" />
      </geometry>
      <material
        name="">
        <color
          rgba="1 1 1 1" />
      </material>
    </visual>
    <collision>
      <origin
        xyz="0 0 0"
        rpy="0 0 0" />
      <geometry>
        <mesh
          filename="package://robot_arm/meshes/Link_3.stl" />
      </geometry>
    </collision>
  </link>
  <joint
    name="joint_3"
    type="revolute">
    <origin
      xyz="0.16947 0.0034106 0"
      rpy="0 0 1.57" />
    <parent
      link="link_2" />
    <child
      link="Link_3" />
    <axis
      xyz="0 0 -1" />
    <limit
      lower="0"
      upper="3.14"
      effort="1.176798"
      velocity="1" />
  </joint>
  <link
    name="link_4">
    <inertial>
      <origin
        xyz="-0.031146 0.0017852 0.0028138"
        rpy="0 0 0" />
      <mass
        value="0.032455" />
      <inertia
        ixx="2.8977E-06"
        ixy="-4.2615E-08"
        ixz="3.4246E-08"
        iyy="3.5978E-06"
        iyz="-4.9594E-07"
        izz="5.1953E-06" />
    </inertial>
    <visual>
      <origin
        xyz="0 0 0"
        rpy="0 0 0" />
      <geometry>
        <mesh
          filename="package://robot_arm/meshes/link_4.stl" />
      </geometry>
      <material
        name="">
        <color
          rgba="0.79216 0.81961 0.93333 1" />
      </material>
    </visual>
    <collision>
      <origin
        xyz="0 0 0"
        rpy="0 0 0" />
      <geometry>
        <mesh
          filename="package://robot_arm/meshes/link_4.stl" />
      </geometry>
    </collision>
  </link>
  <joint
    name="joint_4"
    type="revolute">
    <origin
      xyz="0.060671 0.009338 0.024594"
      rpy="1.5708 0 3.1416" />
    <parent
      link="Link_3" />
    <child
      link="link_4" />
    <axis
      xyz="0.99982 0 -0.01873" />
    <limit
      lower="0"
      upper="3.14"
      effort="1.176798"
      velocity="1" />
  </joint>
</robot>